<?xml version="1.0" ?>
<robot name="torso" xmlns:xacro="http://www.ros.org/wiki/xacro">

<xacro:include filename="$(find torso_description)/urdf/materials.xacro" />
<xacro:include filename="$(find torso_description)/urdf/torso.trans" />
<xacro:include filename="$(find torso_description)/urdf/torso.gazebo" />
<link name="base_link">
  <inertial>
    <origin xyz="0.00011617065581982777 0.0001987147886676531 0.003861680026704299" rpy="0 0 0"/>
    <mass value="0.03383387831439715"/>
    <inertia ixx="7e-06" iyy="7e-06" izz="1.4e-05" ixy="-0.0" iyz="0.0" ixz="0.0"/>
  </inertial>
  <visual>
    <origin xyz="0 0 0" rpy="0 0 0"/>
    <geometry>
      <mesh filename="file://$(find torso_description)/meshes/base_link.stl" scale="0.001 0.001 0.001"/>
    </geometry>
    <material name="silver"/>
  </visual>
  <collision>
    <origin xyz="0 0 0" rpy="0 0 0"/>
    <geometry>
      <mesh filename="file://$(find torso_description)/meshes/base_link.stl" scale="0.001 0.001 0.001"/>
    </geometry>
  </collision>
</link>

<link name="torso_1">
  <inertial>
    <origin xyz="-0.0003615717861448489 -0.04352493787760899 0.07173680905089597" rpy="0 0 0"/>
    <mass value="1.3481459270185834"/>
    <inertia ixx="0.006536" iyy="0.004526" izz="0.004074" ixy="-0.000353" iyz="0.001724" ixz="-0.000148"/>
  </inertial>
  <visual>
    <origin xyz="2.8e-05 -0.000199 -0.006342" rpy="0 0 0"/>
    <geometry>
      <mesh filename="file://$(find torso_description)/meshes/torso_1.stl" scale="0.001 0.001 0.001"/>
    </geometry>
    <material name="silver"/>
  </visual>
  <collision>
    <origin xyz="2.8e-05 -0.000199 -0.006342" rpy="0 0 0"/>
    <geometry>
      <mesh filename="file://$(find torso_description)/meshes/torso_1.stl" scale="0.001 0.001 0.001"/>
    </geometry>
  </collision>
</link>

<link name="shoulder_1">
  <inertial>
    <origin xyz="-0.0008026285020619964 -0.012632938511404956 -0.0025992966371718162" rpy="0 0 0"/>
    <mass value="0.06721028329114163"/>
    <inertia ixx="1.7e-05" iyy="2.8e-05" izz="3.3e-05" ixy="-0.0" iyz="-3e-06" ixz="-0.0"/>
  </inertial>
  <visual>
    <origin xyz="2.8e-05 0.091051 -0.106502" rpy="0 0 0"/>
    <geometry>
      <mesh filename="file://$(find torso_description)/meshes/shoulder_1.stl" scale="0.001 0.001 0.001"/>
    </geometry>
    <material name="silver"/>
  </visual>
  <collision>
    <origin xyz="2.8e-05 0.091051 -0.106502" rpy="0 0 0"/>
    <geometry>
      <mesh filename="file://$(find torso_description)/meshes/shoulder_1.stl" scale="0.001 0.001 0.001"/>
    </geometry>
  </collision>
</link>

<link name="upperarm_1">
  <inertial>
    <origin xyz="0.02053221240763796 -0.07168979199152323 -1.5541428002002755e-05" rpy="0 0 0"/>
    <mass value="0.7964005518324803"/>
    <inertia ixx="0.002858" iyy="0.000163" izz="0.002858" ixy="2e-06" iyz="1e-06" ixz="0.0"/>
  </inertial>
  <visual>
    <origin xyz="0.021501 0.123551 -0.081505" rpy="0 0 0"/>
    <geometry>
      <mesh filename="file://$(find torso_description)/meshes/upperarm_1.stl" scale="0.001 0.001 0.001"/>
    </geometry>
    <material name="silver"/>
  </visual>
  <collision>
    <origin xyz="0.021501 0.123551 -0.081505" rpy="0 0 0"/>
    <geometry>
      <mesh filename="file://$(find torso_description)/meshes/upperarm_1.stl" scale="0.001 0.001 0.001"/>
    </geometry>
  </collision>
</link>

<link name="forearm_1">
  <inertial>
    <origin xyz="0.02095974500156214 -0.11900667913269303 -0.02035210502614901" rpy="0 0 0"/>
    <mass value="1.088969578492718"/>
    <inertia ixx="0.001498" iyy="0.000398" izz="0.001483" ixy="0.000232" iyz="-2e-06" ixz="3e-06"/>
  </inertial>
  <visual>
    <origin xyz="0.000949 0.266753 -0.101993" rpy="0 0 0"/>
    <geometry>
      <mesh filename="file://$(find torso_description)/meshes/forearm_1.stl" scale="0.001 0.001 0.001"/>
    </geometry>
    <material name="silver"/>
  </visual>
  <collision>
    <origin xyz="0.000949 0.266753 -0.101993" rpy="0 0 0"/>
    <geometry>
      <mesh filename="file://$(find torso_description)/meshes/forearm_1.stl" scale="0.001 0.001 0.001"/>
    </geometry>
  </collision>
</link>

<link name="ee_link_1">
  <inertial>
    <origin xyz="-3.20500412433547e-08 2.4594707148661854e-07 0.00011294502366754333" rpy="0 0 0"/>
    <mass value="1.902707681457099e-07"/>
    <inertia ixx="0.0" iyy="0.0" izz="0.0" ixy="0.0" iyz="0.0" ixz="-0.0"/>
  </inertial>
  <visual>
    <origin xyz="-0.006657 0.411441 -0.081569" rpy="0 0 0"/>
    <geometry>
      <mesh filename="file://$(find torso_description)/meshes/ee_link_1.stl" scale="0.001 0.001 0.001"/>
    </geometry>
    <material name="silver"/>
  </visual>
  <collision>
    <origin xyz="-0.006657 0.411441 -0.081569" rpy="0 0 0"/>
    <geometry>
      <mesh filename="file://$(find torso_description)/meshes/ee_link_1.stl" scale="0.001 0.001 0.001"/>
    </geometry>
  </collision>
</link>

<joint name="rotate_22" type="continuous">
  <origin xyz="-2.8e-05 0.000199 0.006342" rpy="0 0 0"/>
  <parent link="base_link"/>
  <child link="torso_1"/>
  <axis xyz="0.0 -0.0 1.0"/>
</joint>

<joint name="rotate_1" type="continuous">
  <origin xyz="0.0 -0.09125 0.10016" rpy="0 0 0"/>
  <parent link="torso_1"/>
  <child link="shoulder_1"/>
  <axis xyz="-0.0 -1.0 -0.0"/>
</joint>

<joint name="rotate_3" type="continuous">
  <origin xyz="-0.021473 -0.0325 -0.024997" rpy="0 0 0"/>
  <parent link="shoulder_1"/>
  <child link="upperarm_1"/>
  <axis xyz="1.0 -0.0 -0.000117"/>
</joint>

<joint name="rotate_5" type="continuous">
  <origin xyz="0.020552 -0.143202 0.020488" rpy="0 0 0"/>
  <parent link="upperarm_1"/>
  <child link="forearm_1"/>
  <axis xyz="0.000117 -6.4e-05 1.0"/>
</joint>

<joint name="rigid_dummy" type="fixed">
  <origin xyz="0.007606 -0.144688 -0.020424" rpy="0 0 0"/>
  <parent link="forearm_1"/>
  <child link="ee_link_1"/>
</joint>

</robot>
