<?xml version="1.0" ?>
<robot name="rl_walk" xmlns:xacro="http://www.ros.org/wiki/xacro">

<xacro:include filename="$(find rl_walk_description)/urdf/materials.xacro" />
<xacro:include filename="$(find rl_walk_description)/urdf/rl_walk.trans" />
<xacro:include filename="$(find rl_walk_description)/urdf/rl_walk.gazebo" />
<link name="base_link">
  <inertial>
    <origin xyz="0.0017305195924670967 -0.0011629138733599918 0.5010453144335133" rpy="0 0 0"/>
    <mass value="6.741980846688683"/>
    <inertia ixx="0.114834" iyy="0.061498" izz="0.064366" ixy="-5e-05" iyz="-0.000844" ixz="-0.004356"/>
  </inertial>
  <visual>
    <origin xyz="0 0 0" rpy="0 0 0"/>
    <geometry>
      <mesh filename="file://$(find rl_walk_description)/meshes/base_link.stl" scale="0.001 0.001 0.001"/>
    </geometry>
    <material name="silver"/>
  </visual>
  <collision>
    <origin xyz="0 0 0" rpy="0 0 0"/>
    <geometry>
      <mesh filename="file://$(find rl_walk_description)/meshes/base_link.stl" scale="0.001 0.001 0.001"/>
    </geometry>
  </collision>
</link>

<link name="right_hipjoint_abd_1">
  <inertial>
    <origin xyz="-0.05591451235293073 4.2200876849279867e-07 -0.047054355779525214" rpy="0 0 0"/>
    <mass value="0.6286646646290869"/>
    <inertia ixx="0.000289" iyy="0.000482" izz="0.000312" ixy="0.0" iyz="0.0" ixz="-0.000113"/>
  </inertial>
  <visual>
    <origin xyz="-0.016264 0.045144 -0.418822" rpy="0 0 0"/>
    <geometry>
      <mesh filename="file://$(find rl_walk_description)/meshes/right_hipjoint_abd_1.stl" scale="0.001 0.001 0.001"/>
    </geometry>
    <material name="silver"/>
  </visual>
  <collision>
    <origin xyz="-0.016264 0.045144 -0.418822" rpy="0 0 0"/>
    <geometry>
      <mesh filename="file://$(find rl_walk_description)/meshes/right_hipjoint_abd_1.stl" scale="0.001 0.001 0.001"/>
    </geometry>
  </collision>
</link>

<link name="left_hipjoint_abd_1">
  <inertial>
    <origin xyz="-0.05591451245482693 4.2190017759263787e-07 -0.047053816044921704" rpy="0 0 0"/>
    <mass value="0.6286646646192796"/>
    <inertia ixx="0.000289" iyy="0.000482" izz="0.000312" ixy="0.0" iyz="0.0" ixz="-0.000113"/>
  </inertial>
  <visual>
    <origin xyz="-0.016264 -0.044856 -0.418822" rpy="0 0 0"/>
    <geometry>
      <mesh filename="file://$(find rl_walk_description)/meshes/left_hipjoint_abd_1.stl" scale="0.001 0.001 0.001"/>
    </geometry>
    <material name="silver"/>
  </visual>
  <collision>
    <origin xyz="-0.016264 -0.044856 -0.418822" rpy="0 0 0"/>
    <geometry>
      <mesh filename="file://$(find rl_walk_description)/meshes/left_hipjoint_abd_1.stl" scale="0.001 0.001 0.001"/>
    </geometry>
  </collision>
</link>

<link name="right_hipjoint_pitch_1">
  <inertial>
    <origin xyz="0.03805282855410244 8.617133419139278e-06 -0.002896064422694855" rpy="0 0 0"/>
    <mass value="0.7994976795430209"/>
    <inertia ixx="0.000395" iyy="0.000382" izz="0.000267" ixy="-0.0" iyz="-3e-06" ixz="2.3e-05"/>
  </inertial>
  <visual>
    <origin xyz="0.024676 0.045143 -0.352322" rpy="0 0 0"/>
    <geometry>
      <mesh filename="file://$(find rl_walk_description)/meshes/right_hipjoint_pitch_1.stl" scale="0.001 0.001 0.001"/>
    </geometry>
    <material name="silver"/>
  </visual>
  <collision>
    <origin xyz="0.024676 0.045143 -0.352322" rpy="0 0 0"/>
    <geometry>
      <mesh filename="file://$(find rl_walk_description)/meshes/right_hipjoint_pitch_1.stl" scale="0.001 0.001 0.001"/>
    </geometry>
  </collision>
</link>

<link name="left_hipjoint_pitch_1">
  <inertial>
    <origin xyz="0.038052828850308 -9.507087615268084e-06 -0.0028955230110439545" rpy="0 0 0"/>
    <mass value="0.7994976235700836"/>
    <inertia ixx="0.000395" iyy="0.000382" izz="0.000267" ixy="0.0" iyz="3e-06" ixz="2.3e-05"/>
  </inertial>
  <visual>
    <origin xyz="0.024676 -0.044857 -0.352322" rpy="0 0 0"/>
    <geometry>
      <mesh filename="file://$(find rl_walk_description)/meshes/left_hipjoint_pitch_1.stl" scale="0.001 0.001 0.001"/>
    </geometry>
    <material name="silver"/>
  </visual>
  <collision>
    <origin xyz="0.024676 -0.044857 -0.352322" rpy="0 0 0"/>
    <geometry>
      <mesh filename="file://$(find rl_walk_description)/meshes/left_hipjoint_pitch_1.stl" scale="0.001 0.001 0.001"/>
    </geometry>
  </collision>
</link>

<link name="Left_lower_leg_1">
  <inertial>
    <origin xyz="0.008957091715372446 -0.026013191657981438 -0.11676881863751223" rpy="0 0 0"/>
    <mass value="0.8322714506735266"/>
    <inertia ixx="0.000938" iyy="0.000845" izz="0.000339" ixy="2e-06" iyz="3e-06" ixz="-7.2e-05"/>
  </inertial>
  <visual>
    <origin xyz="-0.015824 -0.070857 -0.332323" rpy="0 0 0"/>
    <geometry>
      <mesh filename="file://$(find rl_walk_description)/meshes/Left_lower_leg_1.stl" scale="0.001 0.001 0.001"/>
    </geometry>
    <material name="silver"/>
  </visual>
  <collision>
    <origin xyz="-0.015824 -0.070857 -0.332323" rpy="0 0 0"/>
    <geometry>
      <mesh filename="file://$(find rl_walk_description)/meshes/Left_lower_leg_1.stl" scale="0.001 0.001 0.001"/>
    </geometry>
  </collision>
</link>

<link name="right_lower_leg_1">
  <inertial>
    <origin xyz="0.008957099903178445 0.026013772490936796 -0.11676836405601473" rpy="0 0 0"/>
    <mass value="0.8322715098033127"/>
    <inertia ixx="0.000938" iyy="0.000845" izz="0.000339" ixy="-2e-06" iyz="-3e-06" ixz="-7.2e-05"/>
  </inertial>
  <visual>
    <origin xyz="-0.015824 0.071143 -0.332322" rpy="0 0 0"/>
    <geometry>
      <mesh filename="file://$(find rl_walk_description)/meshes/right_lower_leg_1.stl" scale="0.001 0.001 0.001"/>
    </geometry>
    <material name="silver"/>
  </visual>
  <collision>
    <origin xyz="-0.015824 0.071143 -0.332322" rpy="0 0 0"/>
    <geometry>
      <mesh filename="file://$(find rl_walk_description)/meshes/right_lower_leg_1.stl" scale="0.001 0.001 0.001"/>
    </geometry>
  </collision>
</link>

<link name="lower_leg_frame_1">
  <inertial>
    <origin xyz="-0.0001887446404426306 -0.025998260358678582 -0.0678871453539575" rpy="0 0 0"/>
    <mass value="0.10974623051687235"/>
    <inertia ixx="0.000263" iyy="0.000201" izz="7.9e-05" ixy="-0.0" iyz="0.0" ixz="1e-06"/>
  </inertial>
  <visual>
    <origin xyz="-0.015824 -0.070858 -0.192323" rpy="0 0 0"/>
    <geometry>
      <mesh filename="file://$(find rl_walk_description)/meshes/lower_leg_frame_1.stl" scale="0.001 0.001 0.001"/>
    </geometry>
    <material name="silver"/>
  </visual>
  <collision>
    <origin xyz="-0.015824 -0.070858 -0.192323" rpy="0 0 0"/>
    <geometry>
      <mesh filename="file://$(find rl_walk_description)/meshes/lower_leg_frame_1.stl" scale="0.001 0.001 0.001"/>
    </geometry>
  </collision>
</link>

<link name="lower_leg_frame_2">
  <inertial>
    <origin xyz="-0.0001887446794814132 0.026001260655841553 -0.06788668503645574" rpy="0 0 0"/>
    <mass value="0.10974623051687235"/>
    <inertia ixx="0.000263" iyy="0.000201" izz="7.9e-05" ixy="-0.0" iyz="0.0" ixz="1e-06"/>
  </inertial>
  <visual>
    <origin xyz="-0.015824 0.071143 -0.192322" rpy="0 0 0"/>
    <geometry>
      <mesh filename="file://$(find rl_walk_description)/meshes/lower_leg_frame_2.stl" scale="0.001 0.001 0.001"/>
    </geometry>
    <material name="silver"/>
  </visual>
  <collision>
    <origin xyz="-0.015824 0.071143 -0.192322" rpy="0 0 0"/>
    <geometry>
      <mesh filename="file://$(find rl_walk_description)/meshes/lower_leg_frame_2.stl" scale="0.001 0.001 0.001"/>
    </geometry>
  </collision>
</link>

<link name="left_ankle_pitch_1">
  <inertial>
    <origin xyz="-0.0024472821427351157 -0.02600905655481872 0.017103477010797334" rpy="0 0 0"/>
    <mass value="0.799497623570085"/>
    <inertia ixx="0.000395" iyy="0.000382" izz="0.000267" ixy="0.0" iyz="3e-06" ixz="2.3e-05"/>
  </inertial>
  <visual>
    <origin xyz="-0.015825 -0.070859 -0.052323" rpy="0 0 0"/>
    <geometry>
      <mesh filename="file://$(find rl_walk_description)/meshes/left_ankle_pitch_1.stl" scale="0.001 0.001 0.001"/>
    </geometry>
    <material name="silver"/>
  </visual>
  <collision>
    <origin xyz="-0.015825 -0.070859 -0.052323" rpy="0 0 0"/>
    <geometry>
      <mesh filename="file://$(find rl_walk_description)/meshes/left_ankle_pitch_1.stl" scale="0.001 0.001 0.001"/>
    </geometry>
  </collision>
</link>

<link name="right_ankle_pitch_1">
  <inertial>
    <origin xyz="-0.002447282489473738 -0.06399274943591472 0.017103935580121236" rpy="0 0 0"/>
    <mass value="0.7994976795430198"/>
    <inertia ixx="0.000395" iyy="0.000382" izz="0.000267" ixy="-0.0" iyz="-3e-06" ixz="2.3e-05"/>
  </inertial>
  <visual>
    <origin xyz="-0.015825 -0.018859 -0.052322" rpy="0 0 0"/>
    <geometry>
      <mesh filename="file://$(find rl_walk_description)/meshes/right_ankle_pitch_1.stl" scale="0.001 0.001 0.001"/>
    </geometry>
    <material name="silver"/>
  </visual>
  <collision>
    <origin xyz="-0.015825 -0.018859 -0.052322" rpy="0 0 0"/>
    <geometry>
      <mesh filename="file://$(find rl_walk_description)/meshes/right_ankle_pitch_1.stl" scale="0.001 0.001 0.001"/>
    </geometry>
  </collision>
</link>

<link name="right_foot_1">
  <inertial>
    <origin xyz="0.004668527759572067 -0.005778178565594011 -0.036259231393205325" rpy="0 0 0"/>
    <mass value="1.0884519024049462"/>
    <inertia ixx="0.001203" iyy="0.002956" izz="0.002851" ixy="0.000171" iyz="-0.000144" ixz="0.000613"/>
  </inertial>
  <visual>
    <origin xyz="0.024675 0.045143 -0.072322" rpy="0 0 0"/>
    <geometry>
      <mesh filename="file://$(find rl_walk_description)/meshes/right_foot_1.stl" scale="0.001 0.001 0.001"/>
    </geometry>
    <material name="silver"/>
  </visual>
  <collision>
    <origin xyz="0.024675 0.045143 -0.072322" rpy="0 0 0"/>
    <geometry>
      <mesh filename="file://$(find rl_walk_description)/meshes/right_foot_1.stl" scale="0.001 0.001 0.001"/>
    </geometry>
  </collision>
</link>

<link name="left_foot_1">
  <inertial>
    <origin xyz="0.00516852588297818 0.005778896074738964 -0.036258606700094495" rpy="0 0 0"/>
    <mass value="1.0884519419865217"/>
    <inertia ixx="0.001203" iyy="0.002956" izz="0.002851" ixy="-0.000171" iyz="0.000144" ixz="0.000613"/>
  </inertial>
  <visual>
    <origin xyz="0.024675 -0.044859 -0.072322" rpy="0 0 0"/>
    <geometry>
      <mesh filename="file://$(find rl_walk_description)/meshes/left_foot_1.stl" scale="0.001 0.001 0.001"/>
    </geometry>
    <material name="silver"/>
  </visual>
  <collision>
    <origin xyz="0.024675 -0.044859 -0.072322" rpy="0 0 0"/>
    <geometry>
      <mesh filename="file://$(find rl_walk_description)/meshes/left_foot_1.stl" scale="0.001 0.001 0.001"/>
    </geometry>
  </collision>
</link>

<joint name="rotate_13" type="continuous">
  <origin xyz="0.016264 -0.045144 0.418822" rpy="0 0 0"/>
  <parent link="base_link"/>
  <child link="right_hipjoint_abd_1"/>
  <axis xyz="-0.0 6e-06 -1.0"/>
</joint>

<joint name="rotate_12" type="continuous">
  <origin xyz="0.016264 0.044856 0.418822" rpy="0 0 0"/>
  <parent link="base_link"/>
  <child link="left_hipjoint_abd_1"/>
  <axis xyz="-0.0 6e-06 -1.0"/>
</joint>

<joint name="rotate_11" type="continuous">
  <origin xyz="-0.04094 1e-06 -0.0665" rpy="0 0 0"/>
  <parent link="right_hipjoint_abd_1"/>
  <child link="right_hipjoint_pitch_1"/>
  <axis xyz="1.0 -0.0 0.0"/>
</joint>

<joint name="rotate_10" type="continuous">
  <origin xyz="-0.04094 1e-06 -0.0665" rpy="0 0 0"/>
  <parent link="left_hipjoint_abd_1"/>
  <child link="left_hipjoint_pitch_1"/>
  <axis xyz="1.0 -0.0 0.0"/>
</joint>

<joint name="rotate_14" type="continuous">
  <origin xyz="0.0405 0.026 -0.019999" rpy="0 0 0"/>
  <parent link="left_hipjoint_pitch_1"/>
  <child link="Left_lower_leg_1"/>
  <axis xyz="-0.0 1.0 9e-06"/>
</joint>

<joint name="rotate_15" type="continuous">
  <origin xyz="0.0405 -0.026 -0.02" rpy="0 0 0"/>
  <parent link="right_hipjoint_pitch_1"/>
  <child link="right_lower_leg_1"/>
  <axis xyz="-0.0 -1.0 -2e-06"/>
</joint>

<joint name="rotate_16" type="continuous">
  <origin xyz="0.0 1e-06 -0.14" rpy="0 0 0"/>
  <parent link="Left_lower_leg_1"/>
  <child link="lower_leg_frame_1"/>
  <axis xyz="-0.0 1.0 9e-06"/>
</joint>

<joint name="rotate_17" type="continuous">
  <origin xyz="0.0 0.0 -0.14" rpy="0 0 0"/>
  <parent link="right_lower_leg_1"/>
  <child link="lower_leg_frame_2"/>
  <axis xyz="-0.0 -1.0 -2e-06"/>
</joint>

<joint name="rotate_18" type="continuous">
  <origin xyz="1e-06 1e-06 -0.14" rpy="0 0 0"/>
  <parent link="lower_leg_frame_1"/>
  <child link="left_ankle_pitch_1"/>
  <axis xyz="-0.0 1.0 9e-06"/>
</joint>

<joint name="rotate_19" type="continuous">
  <origin xyz="1e-06 0.090002 -0.14" rpy="0 0 0"/>
  <parent link="lower_leg_frame_2"/>
  <child link="right_ankle_pitch_1"/>
  <axis xyz="-0.0 -1.0 -2e-06"/>
</joint>

<joint name="rotate_21" type="continuous">
  <origin xyz="-0.0405 -0.064002 0.02" rpy="0 0 0"/>
  <parent link="right_ankle_pitch_1"/>
  <child link="right_foot_1"/>
  <axis xyz="1.0 -0.0 0.0"/>
</joint>

<joint name="rotate_20" type="continuous">
  <origin xyz="-0.0405 -0.026 0.019999" rpy="0 0 0"/>
  <parent link="left_ankle_pitch_1"/>
  <child link="left_foot_1"/>
  <axis xyz="1.0 0.0 0.0"/>
</joint>

</robot>
