<?xml version="1.0" ?>
<robot name="robit_humanoid" xmlns:xacro="http://www.ros.org/wiki/xacro">

<xacro:include filename="$(find robit_humanoid_description)/urdf/materials.xacro" />
<xacro:include filename="$(find robit_humanoid_description)/urdf/robit_humanoid.trans" />
<xacro:include filename="$(find robit_humanoid_description)/urdf/robit_humanoid.gazebo" />
<link name="base_link">
  <inertial>
    <origin xyz="-0.00073124017212157 0.00010380360011517764 0.47685410184822863" rpy="0 0 0"/>
    <mass value="2.318897971245503"/>
    <inertia ixx="0.021152" iyy="0.039021" izz="0.022615" ixy="4.6e-05" iyz="0.003208" ixz="-0.000287"/>
  </inertial>
  <visual>
    <origin xyz="0 0 0" rpy="0 0 0"/>
    <geometry>
      <mesh filename="file://$(find robit_humanoid_description)/meshes/base_link.stl" scale="0.001 0.001 0.001"/>
    </geometry>
    <material name="silver"/>
  </visual>
  <collision>
    <origin xyz="0 0 0" rpy="0 0 0"/>
    <geometry>
      <mesh filename="file://$(find robit_humanoid_description)/meshes/base_link.stl" scale="0.001 0.001 0.001"/>
    </geometry>
  </collision>
</link>

<link name="Thigh_L_1">
  <inertial>
    <origin xyz="-0.0021914642261905426 -0.0243126235395869 0.004240400157559332" rpy="0 0 0"/>
    <mass value="0.2536450825330369"/>
    <inertia ixx="0.000117" iyy="0.000119" izz="8.3e-05" ixy="-3e-06" iyz="1.1e-05" ixz="7e-06"/>
  </inertial>
  <visual>
    <origin xyz="-0.045287 -0.027088 -0.324643" rpy="0 0 0"/>
    <geometry>
      <mesh filename="file://$(find robit_humanoid_description)/meshes/Thigh_L_1.stl" scale="0.001 0.001 0.001"/>
    </geometry>
    <material name="silver"/>
  </visual>
  <collision>
    <origin xyz="-0.045287 -0.027088 -0.324643" rpy="0 0 0"/>
    <geometry>
      <mesh filename="file://$(find robit_humanoid_description)/meshes/Thigh_L_1.stl" scale="0.001 0.001 0.001"/>
    </geometry>
  </collision>
</link>

<link name="Upper_leg_L_1">
  <inertial>
    <origin xyz="-0.002227029928914423 -0.03712204628534224 -0.10249187610348157" rpy="0 0 0"/>
    <mass value="0.2864108832013868"/>
    <inertia ixx="0.000379" iyy="0.000391" izz="0.000161" ixy="1.9e-05" iyz="-9.2e-05" ixz="4.7e-05"/>
  </inertial>
  <visual>
    <origin xyz="-0.061888 0.014885 -0.347247" rpy="0 0 0"/>
    <geometry>
      <mesh filename="file://$(find robit_humanoid_description)/meshes/Upper_leg_L_1.stl" scale="0.001 0.001 0.001"/>
    </geometry>
    <material name="silver"/>
  </visual>
  <collision>
    <origin xyz="-0.061888 0.014885 -0.347247" rpy="0 0 0"/>
    <geometry>
      <mesh filename="file://$(find robit_humanoid_description)/meshes/Upper_leg_L_1.stl" scale="0.001 0.001 0.001"/>
    </geometry>
  </collision>
</link>

<link name="Lower_leg_L_1">
  <inertial>
    <origin xyz="-0.011997680504420613 0.049166578986702986 -0.06668672980201878" rpy="0 0 0"/>
    <mass value="0.03774711113318724"/>
    <inertia ixx="6.8e-05" iyy="8e-05" izz="3.9e-05" ixy="-5e-06" iyz="2.3e-05" ixz="7e-06"/>
  </inertial>
  <visual>
    <origin xyz="-0.090653 0.075639 -0.224403" rpy="0 0 0"/>
    <geometry>
      <mesh filename="file://$(find robit_humanoid_description)/meshes/Lower_leg_L_1.stl" scale="0.001 0.001 0.001"/>
    </geometry>
    <material name="silver"/>
  </visual>
  <collision>
    <origin xyz="-0.090653 0.075639 -0.224403" rpy="0 0 0"/>
    <geometry>
      <mesh filename="file://$(find robit_humanoid_description)/meshes/Lower_leg_L_1.stl" scale="0.001 0.001 0.001"/>
    </geometry>
  </collision>
</link>

<link name="Hip_L_1">
  <inertial>
    <origin xyz="3.3761577986068936e-07 0.07024615098830349 -0.03793277435686759" rpy="0 0 0"/>
    <mass value="0.21622840603124985"/>
    <inertia ixx="0.000166" iyy="9.2e-05" izz="0.000115" ixy="0.0" iyz="3.7e-05" ixz="-0.0"/>
  </inertial>
  <visual>
    <origin xyz="-0.045287 0.015899 -0.389838" rpy="0 0 0"/>
    <geometry>
      <mesh filename="file://$(find robit_humanoid_description)/meshes/Hip_L_1.stl" scale="0.001 0.001 0.001"/>
    </geometry>
    <material name="silver"/>
  </visual>
  <collision>
    <origin xyz="-0.045287 0.015899 -0.389838" rpy="0 0 0"/>
    <geometry>
      <mesh filename="file://$(find robit_humanoid_description)/meshes/Hip_L_1.stl" scale="0.001 0.001 0.001"/>
    </geometry>
  </collision>
</link>

<link name="Ankle_L_1">
  <inertial>
    <origin xyz="-0.0218153880026319 0.0030053183546911635 -0.02220350726000303" rpy="0 0 0"/>
    <mass value="0.26199635159981133"/>
    <inertia ixx="0.000121" iyy="0.000129" izz="8.7e-05" ixy="-2e-06" iyz="7e-06" ixz="7e-06"/>
  </inertial>
  <visual>
    <origin xyz="-0.118336 -0.002085 -0.098671" rpy="0 0 0"/>
    <geometry>
      <mesh filename="file://$(find robit_humanoid_description)/meshes/Ankle_L_1.stl" scale="0.001 0.001 0.001"/>
    </geometry>
    <material name="silver"/>
  </visual>
  <collision>
    <origin xyz="-0.118336 -0.002085 -0.098671" rpy="0 0 0"/>
    <geometry>
      <mesh filename="file://$(find robit_humanoid_description)/meshes/Ankle_L_1.stl" scale="0.001 0.001 0.001"/>
    </geometry>
  </collision>
</link>

<link name="Foot_L_1">
  <inertial>
    <origin xyz="0.005418637802924731 -0.004213091854653364 -0.03630983392424594" rpy="0 0 0"/>
    <mass value="0.3743721303423568"/>
    <inertia ixx="0.00102" iyy="0.000412" izz="0.000979" ixy="4.5e-05" iyz="-0.000213" ixz="4.5e-05"/>
  </inertial>
  <visual>
    <origin xyz="-0.09953 -0.042976 -0.074228" rpy="0 0 0"/>
    <geometry>
      <mesh filename="file://$(find robit_humanoid_description)/meshes/Foot_L_1.stl" scale="0.001 0.001 0.001"/>
    </geometry>
    <material name="silver"/>
  </visual>
  <collision>
    <origin xyz="-0.09953 -0.042976 -0.074228" rpy="0 0 0"/>
    <geometry>
      <mesh filename="file://$(find robit_humanoid_description)/meshes/Foot_L_1.stl" scale="0.001 0.001 0.001"/>
    </geometry>
  </collision>
</link>

<link name="Hip_R_1">
  <inertial>
    <origin xyz="3.3763605908343486e-07 0.07024615963355266 -0.037932781347330635" rpy="0 0 0"/>
    <mass value="0.2162284709772976"/>
    <inertia ixx="0.000166" iyy="9.2e-05" izz="0.000115" ixy="0.0" iyz="3.7e-05" ixz="-0.0"/>
  </inertial>
  <visual>
    <origin xyz="0.044713 0.015899 -0.389838" rpy="0 0 0"/>
    <geometry>
      <mesh filename="file://$(find robit_humanoid_description)/meshes/Hip_R_1.stl" scale="0.001 0.001 0.001"/>
    </geometry>
    <material name="silver"/>
  </visual>
  <collision>
    <origin xyz="0.044713 0.015899 -0.389838" rpy="0 0 0"/>
    <geometry>
      <mesh filename="file://$(find robit_humanoid_description)/meshes/Hip_R_1.stl" scale="0.001 0.001 0.001"/>
    </geometry>
  </collision>
</link>

<link name="Thigh_R_1">
  <inertial>
    <origin xyz="0.002192109560251801 -0.023566442298204072 0.004315925829178224" rpy="0 0 0"/>
    <mass value="0.25364493522319664"/>
    <inertia ixx="0.000117" iyy="0.000119" izz="8.3e-05" ixy="3e-06" iyz="1.1e-05" ixz="-7e-06"/>
  </inertial>
  <visual>
    <origin xyz="0.044713 -0.027088 -0.324643" rpy="0 0 0"/>
    <geometry>
      <mesh filename="file://$(find robit_humanoid_description)/meshes/Thigh_R_1.stl" scale="0.001 0.001 0.001"/>
    </geometry>
    <material name="silver"/>
  </visual>
  <collision>
    <origin xyz="0.044713 -0.027088 -0.324643" rpy="0 0 0"/>
    <geometry>
      <mesh filename="file://$(find robit_humanoid_description)/meshes/Thigh_R_1.stl" scale="0.001 0.001 0.001"/>
    </geometry>
  </collision>
</link>

<link name="Upper_leg_R_1">
  <inertial>
    <origin xyz="0.0026954077761420434 -0.03693950734286601 -0.10262600859210247" rpy="0 0 0"/>
    <mass value="0.2864109593223628"/>
    <inertia ixx="0.000379" iyy="0.000391" izz="0.000161" ixy="-1.9e-05" iyz="-9.2e-05" ixz="-4.7e-05"/>
  </inertial>
  <visual>
    <origin xyz="0.061314 0.014135 -0.34727" rpy="0 0 0"/>
    <geometry>
      <mesh filename="file://$(find robit_humanoid_description)/meshes/Upper_leg_R_1.stl" scale="0.001 0.001 0.001"/>
    </geometry>
    <material name="silver"/>
  </visual>
  <collision>
    <origin xyz="0.061314 0.014135 -0.34727" rpy="0 0 0"/>
    <geometry>
      <mesh filename="file://$(find robit_humanoid_description)/meshes/Upper_leg_R_1.stl" scale="0.001 0.001 0.001"/>
    </geometry>
  </collision>
</link>

<link name="Lower_Leg_R_1">
  <inertial>
    <origin xyz="0.01198844786165322 0.0490789720306965 -0.06666060524459416" rpy="0 0 0"/>
    <mass value="0.037747111133187426"/>
    <inertia ixx="6.8e-05" iyy="8e-05" izz="3.9e-05" ixy="5e-06" iyz="2.3e-05" ixz="-7e-06"/>
  </inertial>
  <visual>
    <origin xyz="0.089612 0.074671 -0.224222" rpy="0 0 0"/>
    <geometry>
      <mesh filename="file://$(find robit_humanoid_description)/meshes/Lower_Leg_R_1.stl" scale="0.001 0.001 0.001"/>
    </geometry>
    <material name="silver"/>
  </visual>
  <collision>
    <origin xyz="0.089612 0.074671 -0.224222" rpy="0 0 0"/>
    <geometry>
      <mesh filename="file://$(find robit_humanoid_description)/meshes/Lower_Leg_R_1.stl" scale="0.001 0.001 0.001"/>
    </geometry>
  </collision>
</link>

<link name="Ankle_R_1">
  <inertial>
    <origin xyz="0.021814969328014355 0.00297809288127243 -0.02220684824533825" rpy="0 0 0"/>
    <mass value="0.26199655441262554"/>
    <inertia ixx="0.000121" iyy="0.000129" izz="8.7e-05" ixy="2e-06" iyz="7e-06" ixz="-7e-06"/>
  </inertial>
  <visual>
    <origin xyz="0.117309 -0.002862 -0.09847" rpy="0 0 0"/>
    <geometry>
      <mesh filename="file://$(find robit_humanoid_description)/meshes/Ankle_R_1.stl" scale="0.001 0.001 0.001"/>
    </geometry>
    <material name="silver"/>
  </visual>
  <collision>
    <origin xyz="0.117309 -0.002862 -0.09847" rpy="0 0 0"/>
    <geometry>
      <mesh filename="file://$(find robit_humanoid_description)/meshes/Ankle_R_1.stl" scale="0.001 0.001 0.001"/>
    </geometry>
  </collision>
</link>

<link name="Foot_R_1">
  <inertial>
    <origin xyz="-0.005882924681531537 -0.004280274239415724 -0.03622920628887312" rpy="0 0 0"/>
    <mass value="0.3743722024989784"/>
    <inertia ixx="0.001018" iyy="0.000412" izz="0.000981" ixy="-4.7e-05" iyz="-0.000212" ixz="-4.5e-05"/>
  </inertial>
  <visual>
    <origin xyz="0.098516 -0.043721 -0.073965" rpy="0 0 0"/>
    <geometry>
      <mesh filename="file://$(find robit_humanoid_description)/meshes/Foot_R_1.stl" scale="0.001 0.001 0.001"/>
    </geometry>
    <material name="silver"/>
  </visual>
  <collision>
    <origin xyz="0.098516 -0.043721 -0.073965" rpy="0 0 0"/>
    <geometry>
      <mesh filename="file://$(find robit_humanoid_description)/meshes/Foot_R_1.stl" scale="0.001 0.001 0.001"/>
    </geometry>
  </collision>
</link>

<joint name="rotate_10" type="continuous">
  <origin xyz="0.0 0.042987 -0.065195" rpy="0 0 0"/>
  <parent link="Hip_L_1"/>
  <child link="Thigh_L_1"/>
  <axis xyz="-0.0 -0.999517 -0.031085"/>
</joint>

<joint name="rotate_14" type="continuous">
  <origin xyz="0.016601 -0.041973 0.022604" rpy="0 0 0"/>
  <parent link="Thigh_L_1"/>
  <child link="Upper_leg_L_1"/>
  <axis xyz="0.978148 -0.006463 0.207811"/>
</joint>

<joint name="rotate_16" type="continuous">
  <origin xyz="0.028765 -0.060754 -0.122844" rpy="0 0 0"/>
  <parent link="Upper_leg_L_1"/>
  <child link="Lower_leg_L_1"/>
  <axis xyz="-0.978148 0.006463 -0.207811"/>
</joint>

<joint name="rotate_12" type="continuous">
  <origin xyz="0.045287 -0.015899 0.389838" rpy="0 0 0"/>
  <parent link="base_link"/>
  <child link="Hip_L_1"/>
  <axis xyz="0.0 -0.031085 0.999517"/>
</joint>

<joint name="rotate_18" type="continuous">
  <origin xyz="0.027683 0.077724 -0.125732" rpy="0 0 0"/>
  <parent link="Lower_leg_L_1"/>
  <child link="Ankle_L_1"/>
  <axis xyz="0.978148 -0.006463 0.207811"/>
</joint>

<joint name="rotate_20" type="continuous">
  <origin xyz="-0.018806 0.040891 -0.024443" rpy="0 0 0"/>
  <parent link="Ankle_L_1"/>
  <child link="Foot_L_1"/>
  <axis xyz="0.020999 0.997477 -0.067817"/>
</joint>

<joint name="rotate_13" type="continuous">
  <origin xyz="-0.044713 -0.015899 0.389838" rpy="0 0 0"/>
  <parent link="base_link"/>
  <child link="Hip_R_1"/>
  <axis xyz="0.0 -0.031085 0.999517"/>
</joint>

<joint name="rotate_11" type="continuous">
  <origin xyz="0.0 0.042987 -0.065195" rpy="0 0 0"/>
  <parent link="Hip_R_1"/>
  <child link="Thigh_R_1"/>
  <axis xyz="-0.0 -0.999517 -0.031085"/>
</joint>

<joint name="rotate_15" type="continuous">
  <origin xyz="-0.016601 -0.041223 0.022627" rpy="0 0 0"/>
  <parent link="Thigh_R_1"/>
  <child link="Upper_leg_R_1"/>
  <axis xyz="-0.978148 -0.006463 0.207811"/>
</joint>

<joint name="rotate_17" type="continuous">
  <origin xyz="-0.028298 -0.060536 -0.123048" rpy="0 0 0"/>
  <parent link="Upper_leg_R_1"/>
  <child link="Lower_Leg_R_1"/>
  <axis xyz="0.978148 0.006463 -0.207811"/>
</joint>

<joint name="rotate_19" type="continuous">
  <origin xyz="-0.027697 0.077533 -0.125752" rpy="0 0 0"/>
  <parent link="Lower_Leg_R_1"/>
  <child link="Ankle_R_1"/>
  <axis xyz="0.978148 0.006463 -0.207811"/>
</joint>

<joint name="rotate_21" type="continuous">
  <origin xyz="0.018793 0.040859 -0.024505" rpy="0 0 0"/>
  <parent link="Ankle_R_1"/>
  <child link="Foot_R_1"/>
  <axis xyz="0.021323 -0.997365 0.069349"/>
</joint>

</robot>
