<?xml version="1.0" ?>
<robot name="loco_mani_srcirc_2025" xmlns:xacro="http://www.ros.org/wiki/xacro">

<xacro:include filename="$(find loco_mani_srcirc_2025_description)/urdf/materials.xacro" />
<xacro:include filename="$(find loco_mani_srcirc_2025_description)/urdf/loco_mani_srcirc_2025.trans" />
<xacro:include filename="$(find loco_mani_srcirc_2025_description)/urdf/loco_mani_srcirc_2025.gazebo" />
<link name="base_link">
  <inertial>
    <origin xyz="-0.0002956705420842343 -0.002471856627956735 0.0055274660903433335" rpy="0 0 0"/>
    <mass value="0.033833878314397124"/>
    <inertia ixx="7e-06" iyy="7e-06" izz="1.4e-05" ixy="-0.0" iyz="0.0" ixz="0.0"/>
  </inertial>
  <visual>
    <origin xyz="0 0 0" rpy="0 0 0"/>
    <geometry>
      <mesh filename="file://$(find loco_mani_srcirc_2025_description)/meshes/base_link.stl" scale="0.001 0.001 0.001"/>
    </geometry>
    <material name="silver"/>
  </visual>
  <collision>
    <origin xyz="0 0 0" rpy="0 0 0"/>
    <geometry>
      <mesh filename="file://$(find loco_mani_srcirc_2025_description)/meshes/base_link.stl" scale="0.001 0.001 0.001"/>
    </geometry>
  </collision>
</link>

<link name="main_body_1">
  <inertial>
    <origin xyz="-0.00858848471762031 -0.0181418112803982 0.09027124626615488" rpy="0 0 0"/>
    <mass value="2.6597689965634936"/>
    <inertia ixx="0.014599" iyy="0.009865" izz="0.010223" ixy="0.000305" iyz="0.001448" ixz="-0.000641"/>
  </inertial>
  <visual>
    <origin xyz="0.00044 0.002472 -0.008008" rpy="0 0 0"/>
    <geometry>
      <mesh filename="file://$(find loco_mani_srcirc_2025_description)/meshes/main_body_1.stl" scale="0.001 0.001 0.001"/>
    </geometry>
    <material name="silver"/>
  </visual>
  <collision>
    <origin xyz="0.00044 0.002472 -0.008008" rpy="0 0 0"/>
    <geometry>
      <mesh filename="file://$(find loco_mani_srcirc_2025_description)/meshes/main_body_1.stl" scale="0.001 0.001 0.001"/>
    </geometry>
  </collision>
</link>

<link name="head_1">
  <inertial>
    <origin xyz="-0.011246574134141537 -0.014850365615310444 0.03988833501792513" rpy="0 0 0"/>
    <mass value="0.7467191229429816"/>
    <inertia ixx="0.00078" iyy="0.000381" izz="0.000588" ixy="-1.2e-05" iyz="-3.3e-05" ixz="-5.6e-05"/>
  </inertial>
  <visual>
    <origin xyz="-0.017062 -0.018026 -0.153668" rpy="0 0 0"/>
    <geometry>
      <mesh filename="file://$(find loco_mani_srcirc_2025_description)/meshes/head_1.stl" scale="0.001 0.001 0.001"/>
    </geometry>
    <material name="silver"/>
  </visual>
  <collision>
    <origin xyz="-0.017062 -0.018026 -0.153668" rpy="0 0 0"/>
    <geometry>
      <mesh filename="file://$(find loco_mani_srcirc_2025_description)/meshes/head_1.stl" scale="0.001 0.001 0.001"/>
    </geometry>
  </collision>
</link>

<link name="shoulder_1">
  <inertial>
    <origin xyz="0.014454918998395672 -0.01052795343438917 -0.002083084549833386" rpy="0 0 0"/>
    <mass value="0.08387616634243387"/>
    <inertia ixx="2e-05" iyy="4.1e-05" izz="4.6e-05" ixy="3e-06" iyz="-4e-06" ixz="1e-06"/>
  </inertial>
  <visual>
    <origin xyz="0.000451 0.093722 -0.108168" rpy="0 0 0"/>
    <geometry>
      <mesh filename="file://$(find loco_mani_srcirc_2025_description)/meshes/shoulder_1.stl" scale="0.001 0.001 0.001"/>
    </geometry>
    <material name="silver"/>
  </visual>
  <collision>
    <origin xyz="0.000451 0.093722 -0.108168" rpy="0 0 0"/>
    <geometry>
      <mesh filename="file://$(find loco_mani_srcirc_2025_description)/meshes/shoulder_1.stl" scale="0.001 0.001 0.001"/>
    </geometry>
  </collision>
</link>

<link name="upperarm_1">
  <inertial>
    <origin xyz="-0.020519968266097678 -0.06272879729133657 0.00013781354674653745" rpy="0 0 0"/>
    <mass value="1.056487832985982"/>
    <inertia ixx="0.00222" iyy="0.00024" izz="0.002222" ixy="-1e-06" iyz="9e-06" ixz="-0.0"/>
  </inertial>
  <visual>
    <origin xyz="-0.038985 0.126226 -0.083168" rpy="0 0 0"/>
    <geometry>
      <mesh filename="file://$(find loco_mani_srcirc_2025_description)/meshes/upperarm_1.stl" scale="0.001 0.001 0.001"/>
    </geometry>
    <material name="silver"/>
  </visual>
  <collision>
    <origin xyz="-0.038985 0.126226 -0.083168" rpy="0 0 0"/>
    <geometry>
      <mesh filename="file://$(find loco_mani_srcirc_2025_description)/meshes/upperarm_1.stl" scale="0.001 0.001 0.001"/>
    </geometry>
  </collision>
</link>

<link name="forearm_1">
  <inertial>
    <origin xyz="0.015140618156164784 -0.09512082037101222 -0.02048476619985448" rpy="0 0 0"/>
    <mass value="0.840821162104394"/>
    <inertia ixx="0.001745" iyy="0.000548" izz="0.001608" ixy="0.000369" iyz="1e-06" ixz="1e-06"/>
  </inertial>
  <visual>
    <origin xyz="-0.018471 0.252424 -0.103718" rpy="0 0 0"/>
    <geometry>
      <mesh filename="file://$(find loco_mani_srcirc_2025_description)/meshes/forearm_1.stl" scale="0.001 0.001 0.001"/>
    </geometry>
    <material name="silver"/>
  </visual>
  <collision>
    <origin xyz="-0.018471 0.252424 -0.103718" rpy="0 0 0"/>
    <geometry>
      <mesh filename="file://$(find loco_mani_srcirc_2025_description)/meshes/forearm_1.stl" scale="0.001 0.001 0.001"/>
    </geometry>
  </collision>
</link>

<link name="gripper_1">
  <inertial>
    <origin xyz="-0.03043594519033718 -0.03862561903915579 -0.020511298558289162" rpy="0 0 0"/>
    <mass value="0.16829798127835183"/>
    <inertia ixx="0.000167" iyy="7.4e-05" izz="0.000138" ixy="-3e-05" iyz="-0.0" ixz="0.0"/>
  </inertial>
  <visual>
    <origin xyz="-0.01846 0.344624 -0.103718" rpy="0 0 0"/>
    <geometry>
      <mesh filename="file://$(find loco_mani_srcirc_2025_description)/meshes/gripper_1.stl" scale="0.001 0.001 0.001"/>
    </geometry>
    <material name="silver"/>
  </visual>
  <collision>
    <origin xyz="-0.01846 0.344624 -0.103718" rpy="0 0 0"/>
    <geometry>
      <mesh filename="file://$(find loco_mani_srcirc_2025_description)/meshes/gripper_1.stl" scale="0.001 0.001 0.001"/>
    </geometry>
  </collision>
</link>

<joint name="rotate_waist" type="continuous">
  <origin xyz="-0.00044 -0.002472 0.008008" rpy="0 0 0"/>
  <parent link="base_link"/>
  <child link="main_body_1"/>
  <axis xyz="0.0 0.0 1.0"/>
</joint>

<joint name="rotate_head" type="continuous">
  <origin xyz="0.017502 0.020498 0.14566" rpy="0 0 0"/>
  <parent link="main_body_1"/>
  <child link="head_1"/>
  <axis xyz="-0.000117 -1.0 0.0"/>
</joint>

<joint name="rotate_1" type="continuous">
  <origin xyz="-1.1e-05 -0.09125 0.10016" rpy="0 0 0"/>
  <parent link="main_body_1"/>
  <child link="shoulder_1"/>
  <axis xyz="-0.000117 -1.0 -0.0"/>
</joint>

<joint name="rotate_3" type="continuous">
  <origin xyz="0.039436 -0.032504 -0.025" rpy="0 0 0"/>
  <parent link="shoulder_1"/>
  <child link="upperarm_1"/>
  <axis xyz="-1.0 0.000117 -0.0"/>
</joint>

<joint name="rotate_5" type="continuous">
  <origin xyz="-0.020514 -0.126198 0.02055" rpy="0 0 0"/>
  <parent link="upperarm_1"/>
  <child link="forearm_1"/>
  <axis xyz="0.0 0.0 -1.0"/>
</joint>

<joint name="rotate_gripper" type="continuous">
  <origin xyz="-1.1e-05 -0.0922 0.0" rpy="0 0 0"/>
  <parent link="forearm_1"/>
  <child link="gripper_1"/>
  <axis xyz="0.0 0.0 -1.0"/>
</joint>

</robot>
