<?xml version="1.0" ?>
<robot name="src_torso" xmlns:xacro="http://www.ros.org/wiki/xacro">

<xacro:include filename="$(find src_torso_description)/urdf/materials.xacro" />
<xacro:include filename="$(find src_torso_description)/urdf/src_torso.trans" />
<xacro:include filename="$(find src_torso_description)/urdf/src_torso.gazebo" />
<link name="base_link">
  <inertial>
    <origin xyz="0.00014449795003566802 6.187744761021463e-14 -0.002480473640778533" rpy="0 0 0"/>
    <mass value="0.03383387831439633"/>
    <inertia ixx="7e-06" iyy="7e-06" izz="1.4e-05" ixy="-0.0" iyz="0.0" ixz="0.0"/>
  </inertial>
  <visual>
    <origin xyz="0 0 0" rpy="0 0 0"/>
    <geometry>
      <mesh filename="file://$(find src_torso_description)/meshes/base_link.stl" scale="0.001 0.001 0.001"/>
    </geometry>
    <material name="silver"/>
  </visual>
  <collision>
    <origin xyz="0 0 0" rpy="0 0 0"/>
    <geometry>
      <mesh filename="file://$(find src_torso_description)/meshes/base_link.stl" scale="0.001 0.001 0.001"/>
    </geometry>
  </collision>
</link>

<link name="torso_1">
  <inertial>
    <origin xyz="-0.0003612443533365806 -0.04352465252475106 0.07173665541989002" rpy="0 0 0"/>
    <mass value="1.3481459270185865"/>
    <inertia ixx="0.006536" iyy="0.004526" izz="0.004074" ixy="-0.000353" iyz="0.001724" ixz="-0.000148"/>
  </inertial>
  <visual>
    <origin xyz="-0.0 -0.0 0.0" rpy="0 0 0"/>
    <geometry>
      <mesh filename="file://$(find src_torso_description)/meshes/torso_1.stl" scale="0.001 0.001 0.001"/>
    </geometry>
    <material name="silver"/>
  </visual>
  <collision>
    <origin xyz="-0.0 -0.0 0.0" rpy="0 0 0"/>
    <geometry>
      <mesh filename="file://$(find src_torso_description)/meshes/torso_1.stl" scale="0.001 0.001 0.001"/>
    </geometry>
  </collision>
</link>

<link name="shoulder_1">
  <inertial>
    <origin xyz="0.0018054637472919666 -0.011510303052662665 -0.002325896037128905" rpy="0 0 0"/>
    <mass value="0.07511744646934003"/>
    <inertia ixx="1.8e-05" iyy="3.3e-05" izz="3.9e-05" ixy="-2e-06" iyz="-4e-06" ixz="-0.0"/>
  </inertial>
  <visual>
    <origin xyz="0.0 0.09125 -0.10016" rpy="0 0 0"/>
    <geometry>
      <mesh filename="file://$(find src_torso_description)/meshes/shoulder_1.stl" scale="0.001 0.001 0.001"/>
    </geometry>
    <material name="silver"/>
  </visual>
  <collision>
    <origin xyz="0.0 0.09125 -0.10016" rpy="0 0 0"/>
    <geometry>
      <mesh filename="file://$(find src_torso_description)/meshes/shoulder_1.stl" scale="0.001 0.001 0.001"/>
    </geometry>
  </collision>
</link>

<link name="upperarm_1">
  <inertial>
    <origin xyz="-0.020512796469568904 -0.0627306918555113 0.00013812322725874349" rpy="0 0 0"/>
    <mass value="1.0564878329859848"/>
    <inertia ixx="0.00222" iyy="0.00024" izz="0.002222" ixy="-1e-06" iyz="9e-06" ixz="0.0"/>
  </inertial>
  <visual>
    <origin xyz="-0.01953 0.12375 -0.07516" rpy="0 0 0"/>
    <geometry>
      <mesh filename="file://$(find src_torso_description)/meshes/upperarm_1.stl" scale="0.001 0.001 0.001"/>
    </geometry>
    <material name="silver"/>
  </visual>
  <collision>
    <origin xyz="-0.01953 0.12375 -0.07516" rpy="0 0 0"/>
    <geometry>
      <mesh filename="file://$(find src_torso_description)/meshes/upperarm_1.stl" scale="0.001 0.001 0.001"/>
    </geometry>
  </collision>
</link>

<link name="forearm_1">
  <inertial>
    <origin xyz="0.017609220639545405 -0.11659784306625509 -0.020369433563468306" rpy="0 0 0"/>
    <mass value="1.3903503393300478"/>
    <inertia ixx="0.002891" iyy="0.000701" izz="0.002724" ixy="0.000474" iyz="-1e-06" ixz="3e-06"/>
  </inertial>
  <visual>
    <origin xyz="0.00097 0.24995 -0.09571" rpy="0 0 0"/>
    <geometry>
      <mesh filename="file://$(find src_torso_description)/meshes/forearm_1.stl" scale="0.001 0.001 0.001"/>
    </geometry>
    <material name="silver"/>
  </visual>
  <collision>
    <origin xyz="0.00097 0.24995 -0.09571" rpy="0 0 0"/>
    <geometry>
      <mesh filename="file://$(find src_torso_description)/meshes/forearm_1.stl" scale="0.001 0.001 0.001"/>
    </geometry>
  </collision>
</link>

<link name="ee_link_1">
  <inertial>
    <origin xyz="8.738739019804875e-07 -0.00020876801439312365 6.0532070052798925e-06" rpy="0 0 0"/>
    <mass value="1.9027076814570735e-07"/>
    <inertia ixx="0.0" iyy="0.0" izz="0.0" ixy="-0.0" iyz="-0.0" ixz="0.0"/>
  </inertial>
  <visual>
    <origin xyz="-0.003429 0.398773 -0.075297" rpy="0 0 0"/>
    <geometry>
      <mesh filename="file://$(find src_torso_description)/meshes/ee_link_1.stl" scale="0.001 0.001 0.001"/>
    </geometry>
    <material name="silver"/>
  </visual>
  <collision>
    <origin xyz="-0.003429 0.398773 -0.075297" rpy="0 0 0"/>
    <geometry>
      <mesh filename="file://$(find src_torso_description)/meshes/ee_link_1.stl" scale="0.001 0.001 0.001"/>
    </geometry>
  </collision>
</link>

<joint name="rotate_torso" type="continuous">
  <origin xyz="0.0 0.0 0.0" rpy="0 0 0"/>
  <parent link="base_link"/>
  <child link="torso_1"/>
  <axis xyz="-0.0 -0.0 1.0"/>
</joint>

<joint name="rotate_1" type="continuous">
  <origin xyz="-0.0 -0.09125 0.10016" rpy="0 0 0"/>
  <parent link="torso_1"/>
  <child link="shoulder_1"/>
  <axis xyz="-0.0 -1.0 -0.0"/>
</joint>

<joint name="rotate_3" type="continuous">
  <origin xyz="0.01953 -0.0325 -0.025" rpy="0 0 0"/>
  <parent link="shoulder_1"/>
  <child link="upperarm_1"/>
  <axis xyz="-1.0 0.0 -5e-06"/>
</joint>

<joint name="rotate_5" type="continuous">
  <origin xyz="-0.0205 -0.1262 0.02055" rpy="0 0 0"/>
  <parent link="upperarm_1"/>
  <child link="forearm_1"/>
  <axis xyz="-5e-06 3e-06 1.0"/>
</joint>

<joint name="rigid_dummy" type="fixed">
  <origin xyz="0.004399 -0.148823 -0.020413" rpy="0 0 0"/>
  <parent link="forearm_1"/>
  <child link="ee_link_1"/>
</joint>

</robot>
