<?xml version="1.0" ?>
<robot name="RCKO2025" xmlns:xacro="http://www.ros.org/wiki/xacro">

<xacro:include filename="$(find RCKO2025_description)/urdf/materials.xacro" />
<xacro:include filename="$(find RCKO2025_description)/urdf/RCKO2025.trans" />
<xacro:include filename="$(find RCKO2025_description)/urdf/RCKO2025.gazebo" />
<link name="base_link">
  <inertial>
    <origin xyz="-0.0781198333354195 -0.0006518299308106812 0.4399478846677073" rpy="0 0 0"/>
    <mass value="6.741980845925567"/>
    <inertia ixx="0.113784" iyy="0.061497" izz="0.065417" ixy="-0.00012" iyz="-0.000837" ixz="-0.008419"/>
  </inertial>
  <visual>
    <origin xyz="0 0 0" rpy="0 0 0"/>
    <geometry>
      <mesh filename="file://$(find RCKO2025_description)/meshes/base_link.stl" scale="0.001 0.001 0.001"/>
    </geometry>
    <material name="silver"/>
  </visual>
  <collision>
    <origin xyz="0 0 0" rpy="0 0 0"/>
    <geometry>
      <mesh filename="file://$(find RCKO2025_description)/meshes/base_link.stl" scale="0.001 0.001 0.001"/>
    </geometry>
  </collision>
</link>

<link name="left_hipjoint_abd_1">
  <inertial>
    <origin xyz="-0.0596233437641636 -1.5916383786993005e-05 -0.042812233695081636" rpy="0 0 0"/>
    <mass value="0.6286646646290881"/>
    <inertia ixx="0.000271" iyy="0.000482" izz="0.000331" ixy="-0.0" iyz="-0.0" ixz="-0.00011"/>
  </inertial>
  <visual>
    <origin xyz="0.070374 -0.04534 -0.356795" rpy="0 0 0"/>
    <geometry>
      <mesh filename="file://$(find RCKO2025_description)/meshes/left_hipjoint_abd_1.stl" scale="0.001 0.001 0.001"/>
    </geometry>
    <material name="silver"/>
  </visual>
  <collision>
    <origin xyz="0.070374 -0.04534 -0.356795" rpy="0 0 0"/>
    <geometry>
      <mesh filename="file://$(find RCKO2025_description)/meshes/left_hipjoint_abd_1.stl" scale="0.001 0.001 0.001"/>
    </geometry>
  </collision>
</link>

<link name="right_hipjoint_abd_1">
  <inertial>
    <origin xyz="-0.05962271764844841 -1.591164752746954e-05 -0.04281225817161166" rpy="0 0 0"/>
    <mass value="0.6286646646151826"/>
    <inertia ixx="0.000271" iyy="0.000482" izz="0.000331" ixy="-0.0" iyz="-0.0" ixz="-0.00011"/>
  </inertial>
  <visual>
    <origin xyz="0.070371 0.04466 -0.356824" rpy="0 0 0"/>
    <geometry>
      <mesh filename="file://$(find RCKO2025_description)/meshes/right_hipjoint_abd_1.stl" scale="0.001 0.001 0.001"/>
    </geometry>
    <material name="silver"/>
  </visual>
  <collision>
    <origin xyz="0.070371 0.04466 -0.356824" rpy="0 0 0"/>
    <geometry>
      <mesh filename="file://$(find RCKO2025_description)/meshes/right_hipjoint_abd_1.stl" scale="0.001 0.001 0.001"/>
    </geometry>
  </collision>
</link>

<link name="right_hipjoint_pitch_1">
  <inertial>
    <origin xyz="0.03795351737590434 -0.0017766974421925888 -0.000954299033687378" rpy="0 0 0"/>
    <mass value="0.7374479075497384"/>
    <inertia ixx="0.000347" iyy="0.000346" izz="0.000238" ixy="1e-06" iyz="-3e-06" ixz="-3e-05"/>
  </inertial>
  <visual>
    <origin xyz="0.116663 0.044682 -0.293404" rpy="0 0 0"/>
    <geometry>
      <mesh filename="file://$(find RCKO2025_description)/meshes/right_hipjoint_pitch_1.stl" scale="0.001 0.001 0.001"/>
    </geometry>
    <material name="silver"/>
  </visual>
  <collision>
    <origin xyz="0.116663 0.044682 -0.293404" rpy="0 0 0"/>
    <geometry>
      <mesh filename="file://$(find RCKO2025_description)/meshes/right_hipjoint_pitch_1.stl" scale="0.001 0.001 0.001"/>
    </geometry>
  </collision>
</link>

<link name="left_hipjoint_pitch_1">
  <inertial>
    <origin xyz="0.03795174115874955 0.0017985655564198358 -0.0009715126126632612" rpy="0 0 0"/>
    <mass value="0.7374478792065627"/>
    <inertia ixx="0.000347" iyy="0.000346" izz="0.000238" ixy="-2e-06" iyz="1e-06" ixz="-3e-05"/>
  </inertial>
  <visual>
    <origin xyz="0.116168 -0.045318 -0.293334" rpy="0 0 0"/>
    <geometry>
      <mesh filename="file://$(find RCKO2025_description)/meshes/left_hipjoint_pitch_1.stl" scale="0.001 0.001 0.001"/>
    </geometry>
    <material name="silver"/>
  </visual>
  <collision>
    <origin xyz="0.116168 -0.045318 -0.293334" rpy="0 0 0"/>
    <geometry>
      <mesh filename="file://$(find RCKO2025_description)/meshes/left_hipjoint_pitch_1.stl" scale="0.001 0.001 0.001"/>
    </geometry>
  </collision>
</link>

<link name="right_upper_leg__1">
  <inertial>
    <origin xyz="-0.0008668984942271918 0.022238946917568732 -0.1149019351658267" rpy="0 0 0"/>
    <mass value="0.8327131213392032"/>
    <inertia ixx="0.001217" iyy="0.00113" izz="0.00036" ixy="-2e-06" iyz="-3e-06" ixz="-0.000114"/>
  </inertial>
  <visual>
    <origin xyz="0.074661 0.068722 -0.310006" rpy="0 0 0"/>
    <geometry>
      <mesh filename="file://$(find RCKO2025_description)/meshes/right_upper_leg__1.stl" scale="0.001 0.001 0.001"/>
    </geometry>
    <material name="silver"/>
  </visual>
  <collision>
    <origin xyz="0.074661 0.068722 -0.310006" rpy="0 0 0"/>
    <geometry>
      <mesh filename="file://$(find RCKO2025_description)/meshes/right_upper_leg__1.stl" scale="0.001 0.001 0.001"/>
    </geometry>
  </collision>
</link>

<link name="left_upper_leg__1">
  <inertial>
    <origin xyz="-0.0021618860453990613 -0.023349404547272537 -0.11466448257668885" rpy="0 0 0"/>
    <mass value="0.8327131573768546"/>
    <inertia ixx="0.001214" iyy="0.00113" izz="0.000363" ixy="1e-06" iyz="-4e-06" ixz="-0.000123"/>
  </inertial>
  <visual>
    <origin xyz="0.074186 -0.069552 -0.309703" rpy="0 0 0"/>
    <geometry>
      <mesh filename="file://$(find RCKO2025_description)/meshes/left_upper_leg__1.stl" scale="0.001 0.001 0.001"/>
    </geometry>
    <material name="silver"/>
  </visual>
  <collision>
    <origin xyz="0.074186 -0.069552 -0.309703" rpy="0 0 0"/>
    <geometry>
      <mesh filename="file://$(find RCKO2025_description)/meshes/left_upper_leg__1.stl" scale="0.001 0.001 0.001"/>
    </geometry>
  </collision>
</link>

<link name="left_lower_leg_1">
  <inertial>
<<<<<<< HEAD
    <origin xyz="-0.005650281818702613 0.025822001462742536 -0.06772036929997684" rpy="0 0 0"/>
    <mass value="0.10974623051687926"/>
    <inertia ixx="0.000262" iyy="0.000201" izz="8e-05" ixy="-0.0" iyz="-0.0" ixz="-1.4e-05"/>
=======
    <origin xyz="-8.212056945443085e-05 0.02582198317065247 -0.06795536785927819" rpy="0 0 0"/>
    <mass value="0.1097462305168792"/>
    <inertia ixx="0.000263" iyy="0.000201" izz="7.9e-05" ixy="0.0" iyz="-0.0" ixz="1e-06"/>
>>>>>>> parent of 44e5b30 (repush)
  </inertial>
  <visual>
    <origin xyz="0.086132 0.072592 -0.170487" rpy="0 0 0"/>
    <geometry>
      <mesh filename="file://$(find RCKO2025_description)/meshes/left_lower_leg_1.stl" scale="0.001 0.001 0.001"/>
    </geometry>
    <material name="silver"/>
  </visual>
  <collision>
    <origin xyz="0.086132 0.072592 -0.170487" rpy="0 0 0"/>
    <geometry>
      <mesh filename="file://$(find RCKO2025_description)/meshes/left_lower_leg_1.stl" scale="0.001 0.001 0.001"/>
    </geometry>
  </collision>
</link>

<link name="right_lower_leg_1">
  <inertial>
<<<<<<< HEAD
    <origin xyz="-0.005008387197218772 -0.025566931779343473 -0.0675226987376316" rpy="0 0 0"/>
    <mass value="0.10974623051688356"/>
    <inertia ixx="0.000262" iyy="0.000201" izz="8e-05" ixy="-0.0" iyz="-1e-06" ixz="-1.2e-05"/>
=======
    <origin xyz="0.0005403758644122038 -0.025566943522814516 -0.06770626577304717" rpy="0 0 0"/>
    <mass value="0.10974623051688351"/>
    <inertia ixx="0.000263" iyy="0.000201" izz="7.9e-05" ixy="0.0" iyz="-1e-06" ixz="3e-06"/>
>>>>>>> parent of 44e5b30 (repush)
  </inertial>
  <visual>
    <origin xyz="0.087255 -0.072064 -0.170293" rpy="0 0 0"/>
    <geometry>
      <mesh filename="file://$(find RCKO2025_description)/meshes/right_lower_leg_1.stl" scale="0.001 0.001 0.001"/>
    </geometry>
    <material name="silver"/>
  </visual>
  <collision>
    <origin xyz="0.087255 -0.072064 -0.170293" rpy="0 0 0"/>
    <geometry>
      <mesh filename="file://$(find RCKO2025_description)/meshes/right_lower_leg_1.stl" scale="0.001 0.001 0.001"/>
    </geometry>
  </collision>
</link>

<link name="left_ankle_pitch_1">
  <inertial>
<<<<<<< HEAD
    <origin xyz="-0.0012523271413189263 -0.02587212282028315 0.017519682372607585" rpy="0 0 0"/>
    <mass value="0.7617305331247881"/>
    <inertia ixx="0.000377" iyy="0.000355" izz="0.000247" ixy="2e-06" iyz="1e-06" ixz="1.3e-05"/>
=======
    <origin xyz="-0.002684447385301289 -0.02587219041070523 0.017358487086665916" rpy="0 0 0"/>
    <mass value="0.7617305331247872"/>
    <inertia ixx="0.000374" iyy="0.000355" izz="0.00025" ixy="2e-06" iyz="2e-06" ixz="2.3e-05"/>
>>>>>>> parent of 44e5b30 (repush)
  </inertial>
  <visual>
    <origin xyz="0.097226 -0.071989 -0.030646" rpy="0 0 0"/>
    <geometry>
      <mesh filename="file://$(find RCKO2025_description)/meshes/left_ankle_pitch_1.stl" scale="0.001 0.001 0.001"/>
    </geometry>
    <material name="silver"/>
  </visual>
  <collision>
    <origin xyz="0.097226 -0.071989 -0.030646" rpy="0 0 0"/>
    <geometry>
      <mesh filename="file://$(find RCKO2025_description)/meshes/left_ankle_pitch_1.stl" scale="0.001 0.001 0.001"/>
    </geometry>
  </collision>
</link>

<link name="right_ankle_pitch_1">
  <inertial>
<<<<<<< HEAD
    <origin xyz="-0.0009647138858091819 0.026039726449397026 0.017289135778773165" rpy="0 0 0"/>
    <mass value="0.7617304834003347"/>
    <inertia ixx="0.000378" iyy="0.000355" izz="0.000247" ixy="-2e-06" iyz="-2e-06" ixz="1.1e-05"/>
=======
    <origin xyz="-0.002677931766474576 0.02603954060499232 0.017107353866920166" rpy="0 0 0"/>
    <mass value="0.7617304834003356"/>
    <inertia ixx="0.000375" iyy="0.000355" izz="0.00025" ixy="-1e-06" iyz="-3e-06" ixz="2.3e-05"/>
>>>>>>> parent of 44e5b30 (repush)
  </inertial>
  <visual>
    <origin xyz="0.097384 0.072962 -0.03094" rpy="0 0 0"/>
    <geometry>
      <mesh filename="file://$(find RCKO2025_description)/meshes/right_ankle_pitch_1.stl" scale="0.001 0.001 0.001"/>
    </geometry>
    <material name="silver"/>
  </visual>
  <collision>
    <origin xyz="0.097384 0.072962 -0.03094" rpy="0 0 0"/>
    <geometry>
      <mesh filename="file://$(find RCKO2025_description)/meshes/right_ankle_pitch_1.stl" scale="0.001 0.001 0.001"/>
    </geometry>
  </collision>
</link>

<link name="right_foot_1">
  <inertial>
    <origin xyz="0.0014179546955375988 -0.00592191825624204 -0.03650825547499402" rpy="0 0 0"/>
    <mass value="1.0884519024049495"/>
    <inertia ixx="0.001325" iyy="0.002955" izz="0.00273" ixy="0.00016" iyz="-0.000159" ixz="0.000749"/>
  </inertial>
  <visual>
    <origin xyz="0.135891 0.048602 -0.054328" rpy="0 0 0"/>
    <geometry>
      <mesh filename="file://$(find RCKO2025_description)/meshes/right_foot_1.stl" scale="0.001 0.001 0.001"/>
    </geometry>
    <material name="silver"/>
  </visual>
  <collision>
    <origin xyz="0.135891 0.048602 -0.054328" rpy="0 0 0"/>
    <geometry>
      <mesh filename="file://$(find RCKO2025_description)/meshes/right_foot_1.stl" scale="0.001 0.001 0.001"/>
    </geometry>
  </collision>
</link>

<link name="left_foot_1">
  <inertial>
    <origin xyz="0.0020652511099268356 0.005859471466279832 -0.03648673300507772" rpy="0 0 0"/>
    <mass value="1.0884519419711154"/>
    <inertia ixx="0.001299" iyy="0.002955" izz="0.002756" ixy="-0.000162" iyz="0.000156" ixz="0.000724"/>
  </inertial>
  <visual>
    <origin xyz="0.136124 -0.04782 -0.053579" rpy="0 0 0"/>
    <geometry>
      <mesh filename="file://$(find RCKO2025_description)/meshes/left_foot_1.stl" scale="0.001 0.001 0.001"/>
    </geometry>
    <material name="silver"/>
  </visual>
  <collision>
    <origin xyz="0.136124 -0.04782 -0.053579" rpy="0 0 0"/>
    <geometry>
      <mesh filename="file://$(find RCKO2025_description)/meshes/left_foot_1.stl" scale="0.001 0.001 0.001"/>
    </geometry>
  </collision>
</link>

<joint name="rotate_12" type="continuous">
  <origin xyz="-0.070374 0.04534 0.356795" rpy="0 0 0"/>
  <parent link="base_link"/>
  <child link="left_hipjoint_abd_1"/>
  <axis xyz="-0.081939 -0.000324 -0.996637"/>
</joint>

<joint name="rotate_13" type="continuous">
  <origin xyz="-0.070371 -0.04466 0.356824" rpy="0 0 0"/>
  <parent link="base_link"/>
  <child link="right_hipjoint_abd_1"/>
  <axis xyz="-0.081939 -0.000324 -0.996637"/>
</joint>

<joint name="rotate_10" type="continuous">
  <origin xyz="-0.046292 -2.2e-05 -0.06342" rpy="0 0 0"/>
  <parent link="right_hipjoint_abd_1"/>
  <child link="right_hipjoint_pitch_1"/>
  <axis xyz="0.996637 1.4e-05 -0.081939"/>
</joint>

<joint name="rotate_11" type="continuous">
  <origin xyz="-0.045794 -2.2e-05 -0.063461" rpy="0 0 0"/>
  <parent link="left_hipjoint_abd_1"/>
  <child link="left_hipjoint_pitch_1"/>
  <axis xyz="0.996637 1.4e-05 -0.081939"/>
</joint>

<joint name="rotate_15" type="continuous">
  <origin xyz="0.042002 -0.02404 0.016602" rpy="0 0 0"/>
  <parent link="right_hipjoint_pitch_1"/>
  <child link="right_upper_leg__1"/>
  <axis xyz="0.00023 -0.999997 0.002632"/>
</joint>

<joint name="rotate_14" type="continuous">
  <origin xyz="0.041982 0.024234 0.016369" rpy="0 0 0"/>
  <parent link="left_hipjoint_pitch_1"/>
  <child link="left_upper_leg__1"/>
  <axis xyz="-0.000592 0.999975 -0.007027"/>
</joint>

<joint name="rotate_17" type="continuous">
  <origin xyz="-0.011471 -0.00387 -0.139519" rpy="0 0 0"/>
  <parent link="right_upper_leg__1"/>
  <child link="left_lower_leg_1"/>
  <axis xyz="0.00023 -0.999997 0.002632"/>
</joint>

<joint name="rotate_16" type="continuous">
  <origin xyz="-0.013069 0.002512 -0.13941" rpy="0 0 0"/>
  <parent link="left_upper_leg__1"/>
  <child link="right_lower_leg_1"/>
  <axis xyz="-0.000592 0.999975 -0.007027"/>
</joint>

<joint name="rotate_18" type="continuous">
  <origin xyz="-0.009971 -7.5e-05 -0.139647" rpy="0 0 0"/>
  <parent link="right_lower_leg_1"/>
  <child link="left_ankle_pitch_1"/>
  <axis xyz="0.000592 -0.999975 0.007027"/>
</joint>

<joint name="rotate_19" type="continuous">
  <origin xyz="-0.011252 -0.00037 -0.139547" rpy="0 0 0"/>
  <parent link="left_lower_leg_1"/>
  <child link="right_ankle_pitch_1"/>
  <axis xyz="-0.00023 0.999997 -0.002632"/>
</joint>

<joint name="rotate_21" type="continuous">
  <origin xyz="-0.038507 0.02436 0.023388" rpy="0 0 0"/>
  <parent link="right_ankle_pitch_1"/>
  <child link="right_foot_1"/>
  <axis xyz="0.996014 -5e-06 -0.089201"/>
</joint>

<<<<<<< HEAD
<joint name="rotate_20" type="continuous">
  <origin xyz="-0.038898 -0.024169 0.022933" rpy="0 0 0"/>
=======
<joint name="È¸Àü 13" type="continuous">
  <origin xyz="-0.040647 -0.024169 0.019669" rpy="0 0 0"/>
>>>>>>> parent of 44e5b30 (repush)
  <parent link="left_ankle_pitch_1"/>
  <child link="left_foot_1"/>
  <axis xyz="0.997442 8.8e-05 -0.071476"/>
</joint>

</robot>
