<?xml version="1.0" ?>
<robot name="RCKO2025" xmlns:xacro="http://www.ros.org/wiki/xacro">

<xacro:include filename="$(find RCKO2025_description)/urdf/materials.xacro" />
<xacro:include filename="$(find RCKO2025_description)/urdf/RCKO2025.trans" />
<xacro:include filename="$(find RCKO2025_description)/urdf/RCKO2025.gazebo" />
<link name="base_link">
  <inertial>
    <origin xyz="-0.016297126176947143 0.0025458330031376073 0.46299748907258126" rpy="0 0 0"/>
    <mass value="6.741980845925567"/>
    <inertia ixx="0.114834" iyy="0.061497" izz="0.064366" ixy="-5.1e-05" iyz="-0.000843" ixz="-0.004356"/>
  </inertial>
  <visual>
    <origin xyz="0 0 0" rpy="0 0 0"/>
    <geometry>
      <mesh filename="file://$(find RCKO2025_description)/meshes/base_link.stl" scale="0.001 0.001 0.001"/>
    </geometry>
    <material name="silver"/>
  </visual>
  <collision>
    <origin xyz="0 0 0" rpy="0 0 0"/>
    <geometry>
      <mesh filename="file://$(find RCKO2025_description)/meshes/base_link.stl" scale="0.001 0.001 0.001"/>
    </geometry>
  </collision>
</link>

<link name="left_hipjoint_abd_1">
  <inertial>
    <origin xyz="-0.05591415809537886 -1.5871339073603163e-05 -0.04755389203614463" rpy="0 0 0"/>
    <mass value="0.6286646646290881"/>
    <inertia ixx="0.000289" iyy="0.000482" izz="0.000312" ixy="-0.0" iyz="-0.0" ixz="-0.000113"/>
  </inertial>
  <visual>
    <origin xyz="0.001764 -0.048538 -0.380759" rpy="0 0 0"/>
    <geometry>
      <mesh filename="file://$(find RCKO2025_description)/meshes/left_hipjoint_abd_1.stl" scale="0.001 0.001 0.001"/>
    </geometry>
    <material name="silver"/>
  </visual>
  <collision>
    <origin xyz="0.001764 -0.048538 -0.380759" rpy="0 0 0"/>
    <geometry>
      <mesh filename="file://$(find RCKO2025_description)/meshes/left_hipjoint_abd_1.stl" scale="0.001 0.001 0.001"/>
    </geometry>
  </collision>
</link>

<link name="right_hipjoint_abd_1">
  <inertial>
    <origin xyz="-0.05591415817974288 -1.5866569012319698e-05 -0.04755458650877381" rpy="0 0 0"/>
    <mass value="0.6286646646151826"/>
    <inertia ixx="0.000289" iyy="0.000482" izz="0.000312" ixy="-0.0" iyz="-0.0" ixz="-0.000113"/>
  </inertial>
  <visual>
    <origin xyz="0.001764 0.041462 -0.380789" rpy="0 0 0"/>
    <geometry>
      <mesh filename="file://$(find RCKO2025_description)/meshes/right_hipjoint_abd_1.stl" scale="0.001 0.001 0.001"/>
    </geometry>
    <material name="silver"/>
  </visual>
  <collision>
    <origin xyz="0.001764 0.041462 -0.380789" rpy="0 0 0"/>
    <geometry>
      <mesh filename="file://$(find RCKO2025_description)/meshes/right_hipjoint_abd_1.stl" scale="0.001 0.001 0.001"/>
    </geometry>
  </collision>
</link>

<link name="right_hipjoint_pitch_1">
  <inertial>
    <origin xyz="0.0379043656699808 -0.0017774058233399684 0.00215803669318948" rpy="0 0 0"/>
    <mass value="0.7374479075497384"/>
    <inertia ixx="0.000352" iyy="0.000346" izz="0.000233" ixy="1e-06" iyz="-2e-06" ixz="-2.1e-05"/>
  </inertial>
  <visual>
    <origin xyz="0.042704 0.041484 -0.313789" rpy="0 0 0"/>
    <geometry>
      <mesh filename="file://$(find RCKO2025_description)/meshes/right_hipjoint_pitch_1.stl" scale="0.001 0.001 0.001"/>
    </geometry>
    <material name="silver"/>
  </visual>
  <collision>
    <origin xyz="0.042704 0.041484 -0.313789" rpy="0 0 0"/>
    <geometry>
      <mesh filename="file://$(find RCKO2025_description)/meshes/right_hipjoint_pitch_1.stl" scale="0.001 0.001 0.001"/>
    </geometry>
  </collision>
</link>

<link name="left_hipjoint_pitch_1">
  <inertial>
    <origin xyz="0.03790436613028492 0.0017978502289910728 0.0021413949329527338" rpy="0 0 0"/>
    <mass value="0.7374478792065627"/>
    <inertia ixx="0.000352" iyy="0.000346" izz="0.000233" ixy="-2e-06" iyz="1e-06" ixz="-2.1e-05"/>
  </inertial>
  <visual>
    <origin xyz="0.042204 -0.048516 -0.313759" rpy="0 0 0"/>
    <geometry>
      <mesh filename="file://$(find RCKO2025_description)/meshes/left_hipjoint_pitch_1.stl" scale="0.001 0.001 0.001"/>
    </geometry>
    <material name="silver"/>
  </visual>
  <collision>
    <origin xyz="0.042204 -0.048516 -0.313759" rpy="0 0 0"/>
    <geometry>
      <mesh filename="file://$(find RCKO2025_description)/meshes/left_hipjoint_pitch_1.stl" scale="0.001 0.001 0.001"/>
    </geometry>
  </collision>
</link>

<link name="right_upper_leg__1">
  <inertial>
    <origin xyz="0.008551612660915009 0.022238944873896056 -0.11458656880466644" rpy="0 0 0"/>
    <mass value="0.8327131213392032"/>
    <inertia ixx="0.00123" iyy="0.00113" izz="0.000347" ixy="-2e-06" iyz="-4e-06" ixz="-4.2e-05"/>
  </inertial>
  <visual>
    <origin xyz="0.002204 0.065525 -0.333776" rpy="0 0 0"/>
    <geometry>
      <mesh filename="file://$(find RCKO2025_description)/meshes/right_upper_leg__1.stl" scale="0.001 0.001 0.001"/>
    </geometry>
    <material name="silver"/>
  </visual>
  <collision>
    <origin xyz="0.002204 0.065525 -0.333776" rpy="0 0 0"/>
    <geometry>
      <mesh filename="file://$(find RCKO2025_description)/meshes/right_upper_leg__1.stl" scale="0.001 0.001 0.001"/>
    </geometry>
  </collision>
</link>

<link name="left_upper_leg__1">
  <inertial>
    <origin xyz="0.007241030065429671 -0.02334939560791792 -0.11445621861481967" rpy="0 0 0"/>
    <mass value="0.8327131573768546"/>
    <inertia ixx="0.001229" iyy="0.00113" izz="0.000348" ixy="1e-06" iyz="-4e-06" ixz="-5.2e-05"/>
  </inertial>
  <visual>
    <origin xyz="0.001704 -0.072749 -0.333513" rpy="0 0 0"/>
    <geometry>
      <mesh filename="file://$(find RCKO2025_description)/meshes/left_upper_leg__1.stl" scale="0.001 0.001 0.001"/>
    </geometry>
    <material name="silver"/>
  </visual>
  <collision>
    <origin xyz="0.001704 -0.072749 -0.333513" rpy="0 0 0"/>
    <geometry>
      <mesh filename="file://$(find RCKO2025_description)/meshes/left_upper_leg__1.stl" scale="0.001 0.001 0.001"/>
    </geometry>
  </collision>
</link>

<link name="left_lower_leg_1">
  <inertial>
    <origin xyz="-8.212056945443085e-05 0.02582198317065247 -0.06795536785927817" rpy="0 0 0"/>
    <mass value="0.10974623051687926"/>
    <inertia ixx="0.000263" iyy="0.000201" izz="7.9e-05" ixy="0.0" iyz="-0.0" ixz="1e-06"/>
  </inertial>
  <visual>
    <origin xyz="0.002204 0.069395 -0.193786" rpy="0 0 0"/>
    <geometry>
      <mesh filename="file://$(find RCKO2025_description)/meshes/left_lower_leg_1.stl" scale="0.001 0.001 0.001"/>
    </geometry>
    <material name="silver"/>
  </visual>
  <collision>
    <origin xyz="0.002204 0.069395 -0.193786" rpy="0 0 0"/>
    <geometry>
      <mesh filename="file://$(find RCKO2025_description)/meshes/left_lower_leg_1.stl" scale="0.001 0.001 0.001"/>
    </geometry>
  </collision>
</link>

<link name="right_lower_leg_1">
  <inertial>
    <origin xyz="0.0005403758644121504 -0.02556694352281455 -0.0677062657730472" rpy="0 0 0"/>
    <mass value="0.10974623051688356"/>
    <inertia ixx="0.000263" iyy="0.000201" izz="7.9e-05" ixy="0.0" iyz="-1e-06" ixz="3e-06"/>
  </inertial>
  <visual>
    <origin xyz="0.003305 -0.075261 -0.193501" rpy="0 0 0"/>
    <geometry>
      <mesh filename="file://$(find RCKO2025_description)/meshes/right_lower_leg_1.stl" scale="0.001 0.001 0.001"/>
    </geometry>
    <material name="silver"/>
  </visual>
  <collision>
    <origin xyz="0.003305 -0.075261 -0.193501" rpy="0 0 0"/>
    <geometry>
      <mesh filename="file://$(find RCKO2025_description)/meshes/right_lower_leg_1.stl" scale="0.001 0.001 0.001"/>
    </geometry>
  </collision>
</link>

<link name="left_ankle_pitch_1">
  <inertial>
    <origin xyz="-0.0026844530151543702 -0.02587218408919989 0.017358486982995885" rpy="0 0 0"/>
    <mass value="0.7617305331247886"/>
    <inertia ixx="0.000374" iyy="0.000355" izz="0.00025" ixy="2e-06" iyz="2e-06" ixz="2.3e-05"/>
  </inertial>
  <visual>
    <origin xyz="0.0018 -0.075186 -0.053506" rpy="0 0 0"/>
    <geometry>
      <mesh filename="file://$(find RCKO2025_description)/meshes/left_ankle_pitch_1.stl" scale="0.001 0.001 0.001"/>
    </geometry>
    <material name="silver"/>
  </visual>
  <collision>
    <origin xyz="0.0018 -0.075186 -0.053506" rpy="0 0 0"/>
    <geometry>
      <mesh filename="file://$(find RCKO2025_description)/meshes/left_ankle_pitch_1.stl" scale="0.001 0.001 0.001"/>
    </geometry>
  </collision>
</link>

<link name="right_ankle_pitch_1">
  <inertial>
    <origin xyz="-0.0023777503230411894 0.026039657267006668 0.01715148217324003" rpy="0 0 0"/>
    <mass value="0.7617304834003343"/>
    <inertia ixx="0.000375" iyy="0.000355" izz="0.000249" ixy="-1e-06" iyz="-3e-06" ixz="2.1e-05"/>
  </inertial>
  <visual>
    <origin xyz="0.001984 0.069765 -0.053787" rpy="0 0 0"/>
    <geometry>
      <mesh filename="file://$(find RCKO2025_description)/meshes/right_ankle_pitch_1.stl" scale="0.001 0.001 0.001"/>
    </geometry>
    <material name="silver"/>
  </visual>
  <collision>
    <origin xyz="0.001984 0.069765 -0.053787" rpy="0 0 0"/>
    <geometry>
      <mesh filename="file://$(find RCKO2025_description)/meshes/right_ankle_pitch_1.stl" scale="0.001 0.001 0.001"/>
    </geometry>
  </collision>
</link>

<link name="right_foot_1">
  <inertial>
    <origin xyz="0.004403987733357477 -0.005921573975609225 -0.03626861876211406" rpy="0 0 0"/>
    <mass value="1.0884519024049497"/>
    <inertia ixx="0.001212" iyy="0.002955" izz="0.002843" ixy="0.000173" iyz="-0.000146" ixz="0.000624"/>
  </inertial>
  <visual>
    <origin xyz="0.042277 0.045405 -0.07394" rpy="0 0 0"/>
    <geometry>
      <mesh filename="file://$(find RCKO2025_description)/meshes/right_foot_1.stl" scale="0.001 0.001 0.001"/>
    </geometry>
    <material name="silver"/>
  </visual>
  <collision>
    <origin xyz="0.042277 0.045405 -0.07394" rpy="0 0 0"/>
    <geometry>
      <mesh filename="file://$(find RCKO2025_description)/meshes/right_foot_1.stl" scale="0.001 0.001 0.001"/>
    </geometry>
  </collision>
</link>

<link name="left_foot_1">
  <inertial>
    <origin xyz="0.00504798443398731 0.005859814548277609 -0.036194859990575305" rpy="0 0 0"/>
    <mass value="1.088451941971115"/>
    <inertia ixx="0.00119" iyy="0.002955" izz="0.002864" ixy="-0.000174" iyz="0.000142" ixz="0.000595"/>
  </inertial>
  <visual>
    <origin xyz="0.042447 -0.051017 -0.073175" rpy="0 0 0"/>
    <geometry>
      <mesh filename="file://$(find RCKO2025_description)/meshes/left_foot_1.stl" scale="0.001 0.001 0.001"/>
    </geometry>
    <material name="silver"/>
  </visual>
  <collision>
    <origin xyz="0.042447 -0.051017 -0.073175" rpy="0 0 0"/>
    <geometry>
      <mesh filename="file://$(find RCKO2025_description)/meshes/left_foot_1.stl" scale="0.001 0.001 0.001"/>
    </geometry>
  </collision>
</link>

<joint name="rotate_12" type="continuous">
  <origin xyz="-0.001764 0.048538 0.380759" rpy="0 0 0"/>
  <parent link="base_link"/>
  <child link="left_hipjoint_abd_1"/>
  <axis xyz="-0.0 -0.000326 -1.0"/>
</joint>

<joint name="rotate_13" type="continuous">
  <origin xyz="-0.001764 -0.041462 0.380789" rpy="0 0 0"/>
  <parent link="base_link"/>
  <child link="right_hipjoint_abd_1"/>
  <axis xyz="-0.0 -0.000326 -1.0"/>
</joint>

<joint name="rotate_10" type="continuous">
  <origin xyz="-0.04094 -2.2e-05 -0.067" rpy="0 0 0"/>
  <parent link="right_hipjoint_abd_1"/>
  <child link="right_hipjoint_pitch_1"/>
  <axis xyz="1.0 0.0 0.0"/>
</joint>

<joint name="rotate_11" type="continuous">
  <origin xyz="-0.04044 -2.2e-05 -0.067" rpy="0 0 0"/>
  <parent link="left_hipjoint_abd_1"/>
  <child link="left_hipjoint_pitch_1"/>
  <axis xyz="1.0 -0.0 0.0"/>
</joint>

<joint name="rotate_15" type="continuous">
  <origin xyz="0.0405 -0.024041 0.019987" rpy="0 0 0"/>
  <parent link="right_hipjoint_pitch_1"/>
  <child link="right_upper_leg__1"/>
  <axis xyz="-0.0 -0.999997 0.002644"/>
</joint>

<joint name="rotate_14" type="continuous">
  <origin xyz="0.0405 0.024233 0.019754" rpy="0 0 0"/>
  <parent link="left_hipjoint_pitch_1"/>
  <child link="left_upper_leg__1"/>
  <axis xyz="0.0 0.999975 -0.007053"/>
</joint>

<joint name="rotate_17" type="continuous">
  <origin xyz="0.0 -0.00387 -0.13999" rpy="0 0 0"/>
  <parent link="right_upper_leg__1"/>
  <child link="left_lower_leg_1"/>
  <axis xyz="-0.0 -0.999997 0.002644"/>
</joint>

<joint name="rotate_16" type="continuous">
  <origin xyz="-0.001601 0.002512 -0.140012" rpy="0 0 0"/>
  <parent link="left_upper_leg__1"/>
  <child link="right_lower_leg_1"/>
  <axis xyz="0.0 0.999975 -0.007053"/>
</joint>

<joint name="rotate_18" type="continuous">
  <origin xyz="0.001505 -7.5e-05 -0.139995" rpy="0 0 0"/>
  <parent link="right_lower_leg_1"/>
  <child link="left_ankle_pitch_1"/>
  <axis xyz="-0.0 -0.999975 0.007053"/>
</joint>

<joint name="rotate_19" type="continuous">
  <origin xyz="0.00022 -0.00037 -0.139999" rpy="0 0 0"/>
  <parent link="left_lower_leg_1"/>
  <child link="right_ankle_pitch_1"/>
  <axis xyz="0.0 0.999997 -0.002644"/>
</joint>

<joint name="rotate_21" type="continuous">
  <origin xyz="-0.040293 0.02436 0.020153" rpy="0 0 0"/>
  <parent link="right_ankle_pitch_1"/>
  <child link="right_foot_1"/>
  <axis xyz="0.999973 -1.9e-05 -0.007289"/>
</joint>

<joint name="rotate_20" type="continuous">
  <origin xyz="-0.040647 -0.024169 0.019669" rpy="0 0 0"/>
  <parent link="left_ankle_pitch_1"/>
  <child link="left_foot_1"/>
  <axis xyz="0.999945 7.4e-05 0.010493"/>
</joint>

</robot>
